<?xml version="1.0" encoding="UTF-8"?>
<robot xmlns:xacro="http://ros.org/wiki/xacro">
   <!-- This URDF was automatically created by SolidWorks to URDF Exporter! Originally created by Stephen Brawner (brawner@gmail.com) 
     Commit Version: 1.6.0-4-g7f85cfe  Build Version: 1.6.7995.38578
     For more information, please see http://wiki.ros.org/sw_urdf_exporter -->
   <xacro:macro name="slick">
      <link name="base_footprint"/>
      <link name="base_link">
         <inertial>
            <origin xyz="-0.014726 -0.0030305 0.070879" rpy="0 0 0" />
            <mass value="29" />
            <inertia ixx="0.08388" ixy="0.0029113" ixz="-2.449E-05" iyy="0.10673" iyz="-7.8445E-06" izz="0.18392" />
         </inertial>
         <visual>
            <origin xyz="0 0 0" rpy="0 0 -1.57" />
            <geometry>
               <mesh filename="package://slick_description/meshes/slick_base/base_link.STL" />
            </geometry>
            <material name="">
               <color rgba="0.79216 0.81961 0.93333 1" />
            </material>
         </visual>
         <collision>
            <origin xyz="0 0 0" rpy="0 0 -1.57" />
            <geometry>
               <mesh filename="package://slick_description/meshes/slick_base/base_link.STL" />
            </geometry>
         </collision>
      </link>
      <joint name="base_to_footprint" type="fixed">
         <parent link="base_footprint"/>
         <child link="base_link"/>
         <origin xyz="0 0 0.0243" rpy="0 0 0"/>
      </joint>      
      <link name="left_front_wheel_link">
         <inertial>
            <origin xyz="-7.579E-08 -1.2696E-06 -0.10197" rpy="0 0 0" />
            <mass value="0.34801" />
            <inertia ixx="0.00012433" ixy="4.7494E-10" ixz="-7.3833E-10" iyy="0.00012434" iyz="4.3305E-08" izz="0.00012657" />
         </inertial>
         <visual>
            <origin xyz="0 0 0.125945" rpy="0 0 0" />
            <geometry>
               <mesh filename="package://slick_description/meshes/slick_base/left_front_wheel_link.STL" />
            </geometry>
            <material name="">
               <color rgba="0.79216 0.81961 0.93333 1" />
            </material>
         </visual>
         <collision>
            <origin xyz="0 0 0.125945" rpy="0 0 0" />
            <geometry>
               <mesh filename="package://slick_description/meshes/slick_base/left_front_wheel_link.STL" />
            </geometry>
         </collision>
      </link>
      <joint name="left_front_wheel_joint" type="continuous">
         <origin xyz="0.1599 ${0.0775+0.125945} 0.044" rpy="-1.5708 3.14 3.1416" />
         <parent link="base_link" />
         <child link="left_front_wheel_link" />
         <axis xyz="0 0 1" />
      </joint>
      <link name="right_front_wheel_link">
         <inertial>
            <origin xyz="-7.579E-08 1.2696E-06 0.10197" rpy="0 0 0" />
            <mass value="0.34801" />
            <inertia ixx="0.00012433" ixy="-4.7494E-10" ixz="7.3833E-10" iyy="0.00012434" iyz="4.3305E-08" izz="0.00012657" />
         </inertial>
         <visual>
            <origin xyz="0 0 -0.125945" rpy="0 0 0" />
            <geometry>
               <mesh filename="package://slick_description/meshes/slick_base/right_front_wheel_link.STL" />
            </geometry>
            <material name="">
               <color rgba="0.79216 0.81961 0.93333 1" />
            </material>
         </visual>
         <collision>
            <origin xyz="0 0 -0.125945" rpy="0 0 0" />
            <geometry>
               <mesh filename="package://slick_description/meshes/slick_base/right_front_wheel_link.STL" />
            </geometry>
         </collision>
      </link>
      <joint name="right_front_wheel_joint" type="continuous">
         <origin xyz="0.1599 ${-0.0775-0.125945} 0.044" rpy="-1.5708 3.14 -3.1416" />
         <parent link="base_link" />
         <child link="right_front_wheel_link" />
         <axis xyz="0 0 1" />
      </joint>
      <link name="right_rear_wheel_link">
         <inertial>
            <origin xyz="-7.579E-08 -1.2696E-06 -0.10197" rpy="0 0 0" />
            <mass value="0.34801" />
            <inertia ixx="0.00012433" ixy="4.7494E-10" ixz="-7.3833E-10" iyy="0.00012434" iyz="4.3305E-08" izz="0.00012657" />
         </inertial>
         <visual>
            <origin xyz="0 0 0.125945" rpy="0 0 0" />
            <geometry>
               <mesh filename="package://slick_description/meshes/slick_base/right_rear_wheel_link.STL" />
            </geometry>
            <material name="">
               <color rgba="0.79216 0.81961 0.93333 1" />
            </material>
         </visual>
         <collision>
            <origin xyz="0 0 0.125945" rpy="0 0 0" />
            <geometry>
               <mesh filename="package://slick_description/meshes/slick_base/right_rear_wheel_link.STL" />
            </geometry>
         </collision>
      </link>
      <joint name="right_rear_wheel_joint" type="continuous">
         <origin xyz="-0.1599 ${-0.0775-0.125945} 0.046" rpy="1.5708 3.14 -3.1416" />
         <parent link="base_link" />
         <child link="right_rear_wheel_link" />
         <axis xyz="0 0 1" />
      </joint>
      <link name="left_rear_wheel_link">
         <inertial>
            <origin xyz="-7.579E-08 -1.2696E-06 -0.10197" rpy="0 0 0" />
            <mass value="0.34801" />
            <inertia ixx="0.00012433" ixy="4.7494E-10" ixz="-7.3833E-10" iyy="0.00012434" iyz="4.3305E-08" izz="0.00012657" />
         </inertial>
         <visual>
            <origin xyz="0 0 0.125945" rpy="0 0 0" />
            <geometry>
               <mesh filename="package://slick_description/meshes/slick_base/left_rear_wheel_link.STL" />
            </geometry>
            <material name="">
               <color rgba="0.79216 0.81961 0.93333 1" />
            </material>
         </visual>
         <collision>
            <origin xyz="0 0 0.125945" rpy="0 0 0" />
            <geometry>
               <mesh filename="package://slick_description/meshes/slick_base/left_rear_wheel_link.STL" />
            </geometry>
         </collision>
      </link>
      <joint name="left_rear_wheel_joint" type="continuous">
         <origin xyz="-0.1599 ${0.0775+0.125945} 0.044" rpy="-1.5708 3.14 -3.1416" />
         <parent link="base_link" />
         <child link="left_rear_wheel_link" />
         <axis xyz="0 0 1" />
      </joint>
      <link name="lidar_link">
         <inertial>
            <origin xyz="0.022244 0.043615 0.064897" rpy="0 0 0" />
            <mass value="0.15641" />
            <inertia ixx="9.2992E-05" ixy="4.1775E-08" ixz="-9.628E-08" iyy="6.5293E-05" iyz="-5.3476E-06" izz="9.3058E-05" />
         </inertial>
         <visual>
            <origin xyz="-0.0225 ${-0.035/2} -0.07" rpy="0 0 0" />
            <geometry>
               <mesh filename="package://slick_description/meshes/slick_base/lidar_link.STL" />
            </geometry>
            <material name="">
               <color rgba="0.79216 0.81961 0.93333 1" />
            </material>
         </visual>
         <collision>
            <origin xyz="-0.0225 ${-0.035/2} -0.07" rpy="0 0 0" />
            <geometry>
               <mesh filename="package://slick_description/meshes/slick_base/lidar_link.STL" />
            </geometry>
         </collision>
      </link>
      <joint name="lidar_joint" type="fixed">
         <origin xyz="${0.2856+0.075-0.042} ${0.17412+0.07-0.0035} ${0.0087679+0.035/2}" rpy="1.5708 0 2.3562" />
         <parent link="base_link" />
         <child link="lidar_link" />
         <axis xyz="0 0 0" />
      </joint>
      <link name="lidar2_link">
         <inertial>
            <origin xyz="0.022244 0.043615 0.064897" rpy="0 0 0" />
            <mass value="0.15641" />
            <inertia ixx="9.2992E-05" ixy="4.1775E-08" ixz="-9.628E-08" iyy="6.5293E-05" iyz="-5.3476E-06" izz="9.3058E-05" />
         </inertial>
         <visual>
            <origin xyz="-0.0225 ${-0.035/2} -0.07" rpy="0 0 0" />
            <geometry>
               <mesh filename="package://slick_description/meshes/slick_base/lidar2_link.STL" />
            </geometry>
            <material name="">
               <color rgba="0.79216 0.81961 0.93333 1" />
            </material>
         </visual>
         <collision>
            <origin xyz="-0.0225 ${-0.035/2} -0.07" rpy="0 0 0" />
            <geometry>
               <mesh filename="package://slick_description/meshes/slick_base/lidar2_link.STL" />
            </geometry>
         </collision>
      </link>
      <joint name="lidar2_joint" type="fixed">
         <origin xyz="${-0.2856-0.075+0.042} ${-0.17412-0.07+0.0035} ${0.0087679+0.035/2}" rpy="1.5708 0 -0.7854" />
         <parent link="base_link" />
         <child link="lidar2_link" />
         <axis xyz="0 0 0" />
      </joint>
   </xacro:macro>
</robot>
